<?xml version="1.0"?>
<robot name="$(arg robot_name)" xmlns:xacro="http://ros.org/wiki/xacro">
  <xacro:arg name="robot_name" default="my_robot"/> 

  <link name="base_link"> 
    <visual>
      <geometry><box size="0.4 0.4 0.2"/></geometry>
      <material name="gray"><color rgba="0.5 0.5 0.5 1"/></material>
    </visual>
    <collision>
      <geometry><box size="0.4 0.4 0.2"/></geometry>
    </collision>
    <inertial>
      <origin xyz="0 0 0" rpy="0 0 0"/> 
      <mass value="5.0"/>
      <inertia ixx="0.1" iyy="0.1" izz="0.1" ixy="0" ixz="0" iyz="0"/>
    </inertial>
  </link>

  <xacro:macro name="wheel" params="name y_pos">
    <link name="${name}">
      <visual>
        <origin rpy="1.5708 1.5708 0"/>
        <geometry><cylinder radius="0.05" length="0.02"/></geometry>
        <material name="black"><color rgba="0 0 0 1"/></material>
      </visual>
      <collision>
        <origin rpy="1.5708 1.5708 0"/>
        <geometry><cylinder radius="0.05" length="0.02"/></geometry>
        
      </collision>
      <inertial>
        <mass value="0.2"/>
        <inertia ixx="0.001" iyy="0.001" izz="0.001" ixy="0" ixz="0" iyz="0"/>
      </inertial>
    </link>

    <joint name="${name}_joint" type="continuous">
      <parent link="base_link"/>
      <child link="${name}"/>
      <origin xyz="0.04 ${y_pos} -0.07"/>
      <axis xyz="0 1 0"/>
    </joint>

    <transmission name="${name}_trans">
      <type>transmission_interface/SimpleTransmission</type>
      <joint name="${name}_joint">
        <hardwareInterface>hardware_interface/EffortJointInterface</hardwareInterface>
      </joint>
      <actuator name="${name}_motor">
        <hardwareInterface>hardware_interface/EffortJointInterface</hardwareInterface>
        <mechanicalReduction>1</mechanicalReduction>
      </actuator>
    </transmission>
  </xacro:macro>

  <xacro:wheel name="left_wheel" y_pos="0.15"/>
  <xacro:wheel name="right_wheel" y_pos="-0.15"/>

  <xacro:macro name="caster_wheel" params="name x_pos y_pos">
    <link name="${name}">
      <visual>
        <origin rpy="1.5708 1.5708 0"/>
        <geometry><sphere radius="0.03"/></geometry>
        <material name="black"><color rgba="0.2 0.2 0.2 1"/></material>
      </visual>
      <collision>
        <origin rpy="1.5708 1.5708 0"/>
        <geometry><sphere radius="0.03"/></geometry>
      </collision>
      <inertial>
        <mass value="0.05"/> <inertia ixx="0.00001" iyy="0.00001" izz="0.00001" ixy="0" ixz="0" iyz="0"/>
      </inertial>
    </link>

    <joint name="${name}_joint" type="continuous">
      <parent link="base_link"/>
      <child link="${name}"/>
      <origin xyz="${x_pos} ${y_pos} -0.09"/>
      <axis xyz="0 1 1"/> 
    </joint>

    <gazebo reference="${name}">
      <kp>1000000.0</kp>
      <kd>100.0</kd>
      <mu1>0.01</mu1> <mu2>0.01</mu2>
      <fdir1>0 0 1</fdir1>
      <maxVel>0.1</maxVel>
      <minDepth>0.001</minDepth>
      <selfCollide>false</selfCollide>
    </gazebo>
  </xacro:macro>

  <xacro:caster_wheel name="back_caster" x_pos="-0.12" y_pos="0"/>

  <link name="laser_link">
    <visual>
      <geometry><cylinder radius="0.02" length="0.02"/></geometry>
      <material name="blue"><color rgba="0 0 1 1"/></material>
    </visual>
    <collision><geometry><cylinder radius="0.02" length="0.02"/></geometry></collision>
    <inertial>
      <mass value="0.1"/>
      <inertia ixx="0.001" iyy="0.001" izz="0.001" ixy="0.0" ixz="0.0" iyz="0.0"/>
    </inertial>
  </link>

  <joint name="laser_joint" type="fixed">
    <parent link="base_link"/>
    <child link="laser_link"/>
    <origin xyz="0 0 0.15"/>
  </joint>

  <gazebo reference="laser_link">
    <sensor type="ray" name="laser">
      <update_rate>10.0</update_rate>
      <ray>
        <scan>
          <horizontal>
            <samples>360</samples>
            <min_angle>-1.57</min_angle>
            <max_angle>1.57</max_angle>
          </horizontal>
        </scan>
        <range><min>0.12</min><max>10.0</max></range>
      </ray>
      <plugin name="gazebo_ros_laser" filename="libgazebo_ros_laser.so">
        <topicName>scan</topicName>
        <frameName>laser_link</frameName>
      </plugin>
    </sensor>
  </gazebo>

  <gazebo>
    <plugin name="gazebo_ros_control" filename="libgazebo_ros_control.so">
      <robotNamespace>$(arg robot_name)</robotNamespace>
    </plugin>
  </gazebo>

  <gazebo>
    <plugin name="diff_drive_controller" filename="libgazebo_ros_diff_drive.so">
      <leftJoint>left_wheel_joint</leftJoint>
      <rightJoint>right_wheel_joint</rightJoint>
      <wheelSeparation>0.3</wheelSeparation>
      <wheelDiameter>0.1</wheelDiameter>
      <torque>5</torque>
      <commandTopic>cmd_vel</commandTopic>
      <odometryTopic>odom</odometryTopic>
      <odometryFrame>odom</odometryFrame>
      <robotBaseFrame>base_link</robotBaseFrame>
      <publishTf>true</publishTf>
    </plugin>
  </gazebo>

</robot>